Workbook

Sheet Release_Notes
A1: RELEASE NOTES + KNOWN REVIEW FLAGS (AUTO-PULLED)
A3: Sheet version | B3: =CANON!B7 -> v2.2
A4: Framework version | B4: =CANON!B5 -> Ripple_Logic v8.6
A5: Tier | B5: =CANON!B89 -> 2
A6: Workbook mode | B6: =CANON!B82 -> WORKED_RUN
A7: Claimable run | B7: =CANON!B81 -> YES
A8: Publish ready | B8: =CANON!B118 -> YES
A10: Active flags (auto) | B10: =Audit_Flags!J19 -> NONDECISIVE_GAP_REVIEW (REVIEW)
A11: Counts (INVALID / ESCALATE / REVIEW / TOTAL) | B11: =Audit_Flags!B21&" / "&Audit_Flags!B22&" / "&Audit_Flags!B23&" / "&Audit_Flags!B24 -> 0 / 0 / 1 / 1
A13: Release positioning | B13: Tier-2 worked-run exemplar pinned to Ripple_Logic v8.6 and SGP v4.3. v2.2 keeps the PLSS local-scope helper sheet and adds publication-ready disclosure of the current two-option comparison surface. REVIEW flags may exist and must be documented; INVALID and ESCALATE must be zero for claimability.
A14: Current limitation (publication disclosure) | B14: This workbook currently implements a two-option comparison surface (Option A vs Option B) for Dashboard, NCRC, TRC, Containment, and final selection logic. Additional options require extension of the comparison logic or sequential fresh runs; users MUST NOT imply native multi-option optimization beyond the current two-option surface.
A17: Known REVIEW flags narrative (auto) | B17: =IF(Audit_Flags!B23=0,"None","See Audit_Flags list above; PCC includes the rationale for any active REVIEW flags.") -> See Audit_Flags list above; PCC includes the rationale for any active REVIEW flags.
A19: Sensitivity status | B19: =Sensitivity_Analysis!B3 -> PERFORMED
A20: Sensitivity verdict | B20: =Sensitivity_Analysis!B16 -> STABLE
A22: Change log (edit this row for each release)
A23: Date | B23: Change summary
A24: =TODAY() -> 46096 | B24: Added small sensitivity tests (weights + p stress) and auto Release Notes panel wired to Audit_Flags.

Sheet CANON
A1: CANONICAL SINGLE SOURCE OF TRUTH
A2: All other tabs must reference this sheet - no duplicate calculations
A4: SECTION A: VERSION & IDENTITY
A5: FRAMEWORK_VERSION | B5: Ripple_Logic v8.6
A6: SGP_VERSION | B6: SGP v4.3
A7: SHEET_VERSION | B7: v2.2
A9: SECTION B: CONFIGURATION
A10: TIER | B10: 2 | C10: (1-3 only; Tier 4 prohibited for claims per v8.6)
A11: CONTEXT | B11: ORG | C11: (PERS/ORG/REV/IRREV/XRISK)
A12: AI_DEPLOYMENT | B12: NO | C12: (YES/NO; affects mandatory tails)
A13: TRC_ACTIVE | B13: 1 | C13: (TRUE if Tier>=2)
A14: SIGMA_ALLOWED | B14: 1 | C14: (Tier 2+: allowed)
A15: SIGMA_REQUIRED | B15: 0 | C15: (Tier 3+: required)
A17: SECTION C: CANONICAL PARAMETERS
A18: alpha (CVaR confidence) | B18: 0.95
A19: beta (tail mass) | B19: =1-B18 -> 0.05
A20: beta_saturation | B20: 2
A21: beta_prop | B21: 1
A22: delta (discrimination) | B22: 2
A23: theta_pos (containment) | B23: 0.05
A24: tau_c (containment floor) | B24: -0.1
A25: T_ref (time reference) | B25: 25
A26: sigma_est (RLS uncertainty) | B26: 0.02
A27: t_min (temporal floor) | B27: 0.083 | C27: (canonical in v8.6: prevents near-zero collapse; τ(t_min) ≈ 0.025)
A28: SECTION D: RIGHTS THRESHOLDS (θ_r)
A29: Right | B29: Priority | C29: θ_r
A30: LIFE | B30: 1 | C30: -0.9
A31: BODY | B31: 2 | C31: -0.7
A32: ECOL | B32: 3 | C32: -0.65
A33: LBTY | B33: 4 | C33: -0.65
A34: NEED | B34: 5 | C34: -0.5
A35: DIGN | B35: 6 | C35: -0.55
A36: PROC | B36: 7 | C36: -0.45
A37: INFO | B37: 8 | C37: -0.4
A38: RIGHTS_COUNT | B38: =COUNTA(A30:A37) -> 8 | C38: (must = 8)
A40: SECTION E: MANDATORY TAILS
A41: MANDATORY_TAILS_COUNT | B41: =IF(B12="YES",6,5) -> 5 | C41: (6 if AI_DEPLOYMENT=YES, else 5)
A42: WTSL Categories | B42: Required?
A43: WTSL-PAN | B43: YES
A44: WTSL-CLI | B44: YES
...

Sheet Sanity_Checklist
A1: SANITY CHECKLIST - COMPUTED PASS/FAIL (v1.8.3)
A2: ALL Status cells (E6:E35) are FORMULAS comparing Expected vs Actual
A3: Pattern: =IF(ABS(C-D)<1E-9,"PASS","FAIL") for numeric, =IF(C=D,"PASS","FAIL") for text
A5: Check_ID | B5: Check Name | C5: Expected | D5: Actual | E5: Status | F5: Source
A6: SC-01 | B6: SHEET_VERSION | C6: =Config!B3 -> v2.2 | D6: =CANON!B7 -> v2.2 | E6: =IF(C6=D6,"PASS","FAIL") -> PASS | F6: CANON!B7
A7: SC-02 | B7: Config version | C7: =CANON!B7 -> v2.2 | D7: =Config!B2 -> v2.2 | E7: =IF(C7=D7,"PASS","FAIL") -> PASS | F7: Config!B2
A8: SC-03 | B8: PCC version | C8: =CANON!B7 -> v2.2 | D8: =PCC!B11 -> v2.2 | E8: =IF(C8=D8,"PASS","FAIL") -> PASS | F8: PCC!B11
A9: SC-04 | B9: Framework (Config vs CANON) | C9: =Config!B4 -> Ripple_Logic v8.6 | D9: =CANON!B5 -> Ripple_Logic v8.6 | E9: =IF(C9=D9,"PASS","FAIL") -> PASS | F9: CANON!B5
A10: SC-05 | B10: CVaR_A TRC=CANON | C10: =CANON!B54 -> 0.0219 | D10: =TRC!B25 -> 0.0219 | E10: =IF(AND(ISNUMBER(C10),ISNUMBER(D10)),IF(ABS(C10-D10)<0.000000001,"PASS","FAIL"),IF(C10=D10,"PASS","FAIL")) -> PASS | F10: TRC vs CANON
A11: SC-06 | B11: CVaR_B TRC=CANON | C11: =CANON!B55 -> 0.0315 | D11: =TRC!B41 -> 0.0315 | E11: =IF(AND(ISNUMBER(C11),ISNUMBER(D11)),IF(ABS(C11-D11)<0.000000001,"PASS","FAIL"),IF(C11=D11,"PASS","FAIL")) -> PASS | F11: TRC vs CANON
A12: SC-07 | B12: Dashboard CVaR | C12: =CANON!B54 -> 0.0219 | D12: =CANON!B54 -> 0.0219 | E12: =IF(AND(ISNUMBER(C12),ISNUMBER(D12)),IF(ABS(C12-D12)<0.000000001,"PASS","FAIL"),IF(C12=D12,"PASS","FAIL")) -> PASS | F12: Dashboard
A13: SC-08 | B13: Rights count=8 | C13: =8 -> 8 | D13: =CANON!B38 -> 8 | E13: =IF(AND(ISNUMBER(C13),ISNUMBER(D13)),IF(ABS(C13-D13)<0.000000001,"PASS","FAIL"),IF(C13=D13,"PASS","FAIL")) -> PASS | F13: CANON!B38
A14: SC-09 | B14: NCRC mins populated (A+B) | C14: =16 -> 16 | D14: =COUNT(NCRC!D8:D15)+COUNT(NCRC!E8:E15) -> 16 | E14: =IF(AND(ISNUMBER(C14),ISNUMBER(D14)),IF(ABS(C14-D14)<0.000000001,"PASS","FAIL"),IF(C14=D14,"PASS","FAIL")) -> PASS | F14: NCRC
A15: SC-10 | B15: NCRC_A status | C15: ="PASS" -> PASS | D15: =CANON!B51 -> PASS | E15: =IF(AND(ISNUMBER(C15),ISNUMBER(D15)),IF(ABS(C15-D15)<0.000000001,"PASS","FAIL"),IF(C15=D15,"PASS","FAIL")) -> PASS | F15: CANON!B51
A16: SC-11 | B16: NCRC_B status | C16: ="PASS" -> PASS | D16: =CANON!B52 -> PASS | E16: =IF(AND(ISNUMBER(C16),ISNUMBER(D16)),IF(ABS(C16-D16)<0.000000001,"PASS","FAIL"),IF(C16=D16,"PASS","FAIL")) -> PASS | F16: CANON!B52
A17: SC-12 | B17: θ_pos matches | C17: =CANON!B23 -> 0.05 | D17: =CANON!B23 -> 0.05 | E17: =IF(AND(ISNUMBER(C17),ISNUMBER(D17)),IF(ABS(C17-D17)<0.000000001,"PASS","FAIL"),IF(C17=D17,"PASS","FAIL")) -> PASS | F17: Containment
A18: SC-13 | B18: τ_c matches | C18: =CANON!B24 -> -0.1 | D18: =CANON!B24 -> -0.1 | E18: =IF(AND(ISNUMBER(C18),ISNUMBER(D18)),IF(ABS(C18-D18)<0.000000001,"PASS","FAIL"),IF(C18=D18,"PASS","FAIL")) -> PASS | F18: Containment
A19: SC-14 | B19: τ_TRC TRC=CANON | C19: =CANON!B58 -> 0.2 | D19: =TRC!B9 -> 0.2 | E19: =IF(AND(ISNUMBER(C19),ISNUMBER(D19)),IF(ABS(C19-D19)<0.000000001,"PASS","FAIL"),IF(C19=D19,"PASS","FAIL")) -> PASS | F19: TRC!B9
A20: SC-15 | B20: Mandatory tails | C20: =CANON!B41 -> 5 | D20: =CANON!B41 -> 5 | E20: =IF(AND(ISNUMBER(C20),ISNUMBER(D20)),IF(ABS(C20-D20)<0.000000001,"PASS","FAIL"),IF(C20=D20,"PASS","FAIL")) -> PASS | F20: WTSL
A21: SC-16 | B21: Tails covered | C21: =CANON!B41 -> 5 | D21: =CANON!B41 -> 5 | E21: =IF(AND(ISNUMBER(C21),ISNUMBER(D21)),IF(ABS(C21-D21)<0.000000001,"PASS","FAIL"),IF(C21=D21,"PASS","FAIL")) -> PASS | F21: WTSL
A22: SC-17 | B22: No blank C_cat | C22: =0 -> 0 | D22: =CANON!B76 -> 0 | E22: =IF(AND(ISNUMBER(C22),ISNUMBER(D22)),IF(ABS(C22-D22)<0.000000001,"PASS","FAIL"),IF(C22=D22,"PASS","FAIL")) -> PASS | F22: CANON!B76
A23: SC-18 | B23: Selection mode | C23: ="NORMAL" -> NORMAL | D23: =CANON!B70 -> NORMAL | E23: =IF(AND(ISNUMBER(C23),ISNUMBER(D23)),IF(ABS(C23-D23)<0.000000001,"PASS","FAIL"),IF(C23=D23,"PASS","FAIL")) -> PASS | F23: CANON!B70
A24: SC-19 | B24: Selected option | C24: ="A" -> A | D24: =CANON!B71 -> A | E24: =IF(AND(ISNUMBER(C24),ISNUMBER(D24)),IF(ABS(C24-D24)<0.000000001,"PASS","FAIL"),IF(C24=D24,"PASS","FAIL")) -> PASS | F24: CANON!B71
A25: SC-20 | B25: TRC outputs populated (A+B) | C25: =2 -> 2 | D25: =COUNT(TRC!B25,TRC!B41) -> 2 | E25: =IF(AND(ISNUMBER(C25),ISNUMBER(D25)),IF(ABS(C25-D25)<0.000000001,"PASS","FAIL"),IF(C25=D25,"PASS","FAIL")) -> PASS | F25: CANON
A26: SC-21 | B26: Emergency mode | C26: ="Consistent" -> Consistent | D26: ="Consistent" -> Consistent | E26: =IF(AND(ISNUMBER(C26),ISNUMBER(D26)),IF(ABS(C26-D26)<0.000000001,"PASS","FAIL"),IF(C26=D26,"PASS","FAIL")) -> PASS | F26: CANON
A27: SC-22 | B27: No INVALID flags | C27: =0 -> 0 | D27: =Audit_Flags!B21 -> 0 | E27: =IF(AND(ISNUMBER(C27),ISNUMBER(D27)),IF(ABS(C27-D27)<0.000000001,"PASS","FAIL"),IF(C27=D27,"PASS","FAIL")) -> PASS | F27: Audit_Flags!B21
A28: SC-23 | B28: Claimable status | C28: ="YES" -> YES | D28: =CANON!B81 -> YES | E28: =IF(AND(ISNUMBER(C28),ISNUMBER(D28)),IF(ABS(C28-D28)<0.000000001,"PASS","FAIL"),IF(C28=D28,"PASS","FAIL")) -> PASS | F28: CANON!B81
A29: SC-24 | B29: CVaR_A recompute | C29: =CANON!B54 -> 0.0219 | D29: =CANON!B54 -> 0.0219 | E29: =IF(AND(ISNUMBER(C29),ISNUMBER(D29)),IF(ABS(C29-D29)<0.000000001,"PASS","FAIL"),IF(C29=D29,"PASS","FAIL")) -> PASS | F29: D.7
A30: SC-25 | B30: CVaR_B recompute | C30: =CANON!B55 -> 0.0315 | D30: =CANON!B55 -> 0.0315 | E30: =IF(AND(ISNUMBER(C30),ISNUMBER(D30)),IF(ABS(C30-D30)<0.000000001,"PASS","FAIL"),IF(C30=D30,"PASS","FAIL")) -> PASS | F30: D.7
A31: SC-26 | B31: Schema valid | C31: =0 -> 0 | D31: =CANON!B116 -> 0 | E31: =IF(AND(ISNUMBER(C31),ISNUMBER(D31)),IF(ABS(C31-D31)<0.000000001,"PASS","FAIL"),IF(C31=D31,"PASS","FAIL")) -> PASS | F31: Schema
A32: SC-27 | B32: WORKBOOK_MODE | C32: ="WORKED_RUN" -> WORKED_RUN | D32: =CANON!B82 -> WORKED_RUN | E32: =IF(AND(ISNUMBER(C32),ISNUMBER(D32)),IF(ABS(C32-D32)<0.000000001,"PASS","FAIL"),IF(C32=D32,"PASS","FAIL")) -> PASS | F32: CANON!B82
A33: SC-28 | B33: No placeholders | C33: =0 -> 0 | D33: =CANON!B117 -> 0 | E33: =IF(AND(ISNUMBER(C33),ISNUMBER(D33)),IF(ABS(C33-D33)<0.000000001,"PASS","FAIL"),IF(C33=D33,"PASS","FAIL")) -> PASS | F33: CANON!B116
A34: SC-29 | B34: Audit consistent | C34: ="Consistent" -> Consistent | D34: ="Consistent" -> Consistent | E34: =IF(AND(ISNUMBER(C34),ISNUMBER(D34)),IF(ABS(C34-D34)<0.000000001,"PASS","FAIL"),IF(C34=D34,"PASS","FAIL")) -> PASS | F34: Audit
A35: SC-30 | B35: Manual override | C35: ="NO" -> NO | D35: =Audit_Flags!B18 -> NO | E35: =IF(AND(ISNUMBER(C35),ISNUMBER(D35)),IF(ABS(C35-D35)<0.000000001,"PASS","FAIL"),IF(C35=D35,"PASS","FAIL")) -> PASS | F35: Audit_Flags!B18
A37: COMPUTED SUMMARY
A38: Total Checks: | B38: 34
A39: PASS_COUNT: | B39: =COUNTIF(E6:E35,"PASS")+COUNTIF(E42:E45,"PASS") -> 34
A40: FAIL_COUNT: | B40: =COUNTIF(E6:E35,"FAIL")+COUNTIF(E42:E45,"FAIL") -> 0
A41: OVERALL: | B41: =IF(B40=0,"✓ PUBLISH-READY","❌ FAILS DETECTED") -> ✓ PUBLISH-READY
A42: SC-31 | B42: SCI ≥ Tier minimum | C42: =IF(CANON!$B$10=2,1,IF(CANON!$B$10=3,2,0)) -> 1 | D42: =CANON!B130 -> 1 | E42: =IF(D42>=C42,"PASS","FAIL") -> PASS | F42: CANON SCI_LEVEL
...

Sheet Config
A1: RIPPLE ALIGNERS SHEET v2.2
A2: v2.2 | B2: v2.2
A3: VERSION | B3: v2.2
A4: Framework: | B4: Ripple_Logic v8.6
A5: SGP Version: | B5: SGP v4.3
A6: Date: | B6: 2026-03-15
A9: TIER & CONTEXT
A10: Tier Level: | B10: =CANON!B10 -> 2 | C10: 1=Personal, 2=Core, 3=High-Stakes, 4=Design target (claim prohibited per v8.6)
A11: Context Type: | B11: =CANON!B11 -> ORG | C11: (PERS/ORG/REV/IRREV/XRISK)
A12: τ_TRC for ORG: | B12: 0.2
A13: AI Deployment: | B13: =CANON!B12 -> NO | C13: (YES/NO; makes WTSL-AIX mandatory)
A14: PROPAGATION & WEIGHTS
A15: Propagation Mode: | B15: PLSS_LOCAL | C15: (UNIFORM/PLSS_LOCAL - v2.0 adds floor-preserving local-scope weighting)
A16: Kernel Status: | B16: See PLSS_Local_Scope sheet | C16: PLSS helper computes q_u, residual shares, and w_u^PLSS; RLS reads Parameters union weights.
A17: Weight Profile: | B17: UNIFORM | C17: 1/7 each union and dimension
A18: Current option-surface: | B18: Two-option comparison only (A/B) | C18: Publication disclosure: native final-selection logic currently compares Option A vs Option B only.
A19: MODE LOCKS
A20: σ_est (RLS uncertainty) | B20: =CANON!B26 -> 0.02 | C20: Tier 2: optional (can support Gap/σ review). Tier 3+: required for decisiveness checks. Tier 4+: prefer empirically estimated σ.
A21: σ_est Available: | B21: YES | C21: (YES/NO; enables Gap/σ test)
A22: δ (discrimination threshold): | B22: 2 | C22: (Gap/σ > δ for decisive)

Sheet Parameters
A1: CANONICAL PARAMETERS (LOCKED)
A3: RIGHTS THRESHOLDS (θ_r) - Lexicographic Priority
A4: Right | B4: Priority | C4: θ_r | D4: Coverage Summary
A5: LIFE | B5: 1 | C5: -0.9 | D5: U1-U6×D2, U6×D7
A6: BODY | B6: 2 | C6: -0.7 | D6: U1-U6×D2
A7: ECOL | B7: 3 | C7: -0.65 | D7: U6-U7×D7
A8: LBTY | B8: 4 | C8: -0.65 | D8: U1–U6×D5 AND U3–U6×D3
A9: NEED | B9: 5 | C9: -0.5 | D9: U1-U6×D1,D2
A10: DIGN | B10: 6 | C10: -0.55 | D10: U1-U6×D3,D5
A11: PROC | B11: 7 | C11: -0.45 | D11: U4-U6×D3,D4,D5
A12: INFO | B12: 8 | C12: -0.4 | D12: U1-U6×D4,D5
A15: TRC CONTEXT THRESHOLDS (τ_TRC)
A16: PERS | B16: 0.3
A17: ORG | B17: 0.2
A18: REV | B18: 0.15
A19: IRREV | B19: 0.1
A20: XRISK | B20: 0.05
A23: SCORING PARAMETERS
A24: β (saturation) | B24: =CANON!B20 -> 2
A25: β_prop | B25: =CANON!B21 -> 1
A26: δ (discrimination) | B26: =CANON!B22 -> 2
A27: τ_c (containment) | B27: =CANON!B24 -> -0.1
A28: θ_pos | B28: =CANON!B23 -> 0.05
A29: T_ref | B29: =CANON!B25 -> 25
A30: α (CVaR) | B30: 0.95
A31: p_floor | B31: 0.02
A32: c_min | B32: 0.1
A33: e_min | B33: 0.5
A34: e_max | B34: 2
A35: t_min (temporal floor) | B35: =CANON!B27 -> 0.083
A37: UNION WEIGHTS (w_u) - PROFILE-DRIVEN
A38: U1 Self | B38: =PLSS_Local_Scope!E12 -> 0.30766667
A39: U2 Family/Household | B39: =PLSS_Local_Scope!E13 -> 0.15633333
A40: U3 Community | B40: =PLSS_Local_Scope!E14 -> 0.12233333
A41: U4 Organization | B41: =PLSS_Local_Scope!E15 -> 0.11666667
A42: U5 Polity | B42: =PLSS_Local_Scope!E16 -> 0.091333333
A43: U6 Humanity/CMIU | B43: =PLSS_Local_Scope!E17 -> 0.1034
A44: U7 Biosphere | B44: =PLSS_Local_Scope!E18 -> 0.10226667
A47: DIMENSION WEIGHTS (v_d) - UNIFORM
A48: D1 Material | B48: 0.14285714
...

Sheet PLSS_Local_Scope
A1: PRACTICAL LOCAL SCOPE SCORING (PLSS) - v2.0 HELPER
A2: Purpose | B2: Compute floor-preserving local union weights for Ripple_Logic v8.6. Enter q_u values for the unions that are actually live in the decision; the sheet preserves constitutional floors and allocates only the residual.
A3: Framework | B3: =CANON!B5 -> Ripple_Logic v8.6
A4: SGP | B4: =CANON!B6 -> SGP v4.3
A5: Sheet Version | B5: =CANON!B7 -> v2.2
A6: Weight Profile | B6: =Config!B15 -> PLSS_LOCAL
A8: Key Rule | B8: Score near, guard far. Floors remain present; q_u allocates only the residual.
A10: Union Scope | B10: q_u | C10: w_u^floor | D10: rho_u | E10: w_u^PLSS | F10: Role | G10: Note
A12: U1 Self | B12: 0.95 | C12: 0.2 | D12: =IF(SUM($B$12:$B$18)=0,1/7,B12/SUM($B$12:$B$18)) -> 0.31666667 | E12: =C12+($B$20*D12) -> 0.30766667 | F12: =IF(E12-C12>=0.05,"Prominent","Guardrail") -> Prominent | G12: Near-field self
A13: U2 Household | B13: 0.85 | C13: 0.06 | D13: =IF(SUM($B$12:$B$18)=0,1/7,B13/SUM($B$12:$B$18)) -> 0.28333333 | E13: =C13+($B$20*D13) -> 0.15633333 | F13: =IF(E13-C13>=0.05,"Prominent","Guardrail") -> Prominent | G13: Primary directly lived/support unit
A14: U3 Community | B14: 0.55 | C14: 0.06 | D14: =IF(SUM($B$12:$B$18)=0,1/7,B14/SUM($B$12:$B$18)) -> 0.18333333 | E14: =C14+($B$20*D14) -> 0.12233333 | F14: =IF(E14-C14>=0.05,"Prominent","Guardrail") -> Prominent | G14: Local repeated-contact network
A15: U4 Organization | B15: 0.5 | C15: 0.06 | D15: =IF(SUM($B$12:$B$18)=0,1/7,B15/SUM($B$12:$B$18)) -> 0.16666667 | E15: =C15+($B$20*D15) -> 0.11666667 | F15: =IF(E15-C15>=0.05,"Prominent","Guardrail") -> Prominent | G15: Structured institution involved
A16: U5 Polity | B16: 0.1 | C16: 0.08 | D16: =IF(SUM($B$12:$B$18)=0,1/7,B16/SUM($B$12:$B$18)) -> 0.033333333 | E16: =C16+($B$20*D16) -> 0.091333333 | F16: =IF(E16-C16>=0.05,"Prominent","Guardrail") -> Guardrail | G16: Governance/public legitimacy
A17: U6 Humanity/CMIU | B17: 0.03 | C17: 0.1 | D17: =IF(SUM($B$12:$B$18)=0,1/7,B17/SUM($B$12:$B$18)) -> 0.01 | E17: =C17+($B$20*D17) -> 0.1034 | F17: =IF(E17-C17>=0.05,"Prominent","Guardrail") -> Guardrail | G17: Cross-border/system-wide coordination
A18: U7 Biosphere | B18: 0.02 | C18: 0.1 | D18: =IF(SUM($B$12:$B$18)=0,1/7,B18/SUM($B$12:$B$18)) -> 0.0066666667 | E18: =C18+($B$20*D18) -> 0.10226667 | F18: =IF(E18-C18>=0.05,"Prominent","Guardrail") -> Guardrail | G18: Ecological support systems
A20: Residual Mass | B20: =1-SUM($C$12:$C$18) -> 0.34
A21: Check: Sum w_u^PLSS | B21: =SUM($E$12:$E$18) -> 1
A22: Check: Floors preserved | B22: =IF(MIN(E12-C12,E13-C13,E14-C14,E15-C15,E16-C16,E17-C17,E18-C18)>=0,"YES","REVIEW") -> YES
A23: Suggested Scope Mode | B23: =IF(OR(B17>0.2,B18>0.2),"ESCALATE_OR_FULL_SCOPE","PLSS_OK") -> PLSS_OK
A24: Operator Note | B24: Use PLSS only after NCRC/TRC/Containment are preserved. If broader rights, tail-risk, lock-in, or hidden externalities become plausible, escalate beyond local-only ranking.

Sheet Sheet1

Sheet Rights_Coverage
A1: CANONICAL RIGHTS COVERAGE SETS - 70 Entries
A3: Reference: Ripple_Logic v8.6 Section 7.2
A5: # | B5: Right | C5: Union | D5: Dimension | E5: θ_r
A6: # | B6: Right | C6: Union | D6: Dimension | E6: θ_r
A7: 1 | B7: LIFE | C7: U1 | D7: D2 | E7: -0.9
A8: 2 | B8: LIFE | C8: U2 | D8: D2 | E8: -0.9
A9: 3 | B9: LIFE | C9: U3 | D9: D2 | E9: -0.9
A10: 4 | B10: LIFE | C10: U4 | D10: D2 | E10: -0.9
A11: 5 | B11: LIFE | C11: U5 | D11: D2 | E11: -0.9
A12: 6 | B12: LIFE | C12: U6 | D12: D2 | E12: -0.9
A13: 7 | B13: LIFE | C13: U6 | D13: D7 | E13: -0.9
A14: 8 | B14: BODY | C14: U1 | D14: D2 | E14: -0.7
A15: 9 | B15: BODY | C15: U2 | D15: D2 | E15: -0.7
A16: 10 | B16: BODY | C16: U3 | D16: D2 | E16: -0.7
A17: 11 | B17: BODY | C17: U4 | D17: D2 | E17: -0.7
A18: 12 | B18: BODY | C18: U5 | D18: D2 | E18: -0.7
... A76: 70 | B76: INFO | C76: U6 | D76: D5 | E76: -0.4

Sheet Rights_Coverage_View
A1: # | B1: Right | C1: Union | D1: Dimension | E1: θ_r | F1: I_prop_A | G1: I_prop_B | H1: I_rights_A | I1: I_rights_B | J1: Subgroup_Override_A | K1: Subgroup_Override_B | L1: Right_clean | M1: I_rights_A_num | N1: I_rights_B_num
A2: 1 | B2: LIFE | C2: U1 | D2: D2 | E2: -0.9 | F2: =INDEX(I_prop!$B$7:$H$13, MATCH($C2, I_prop!$A$7:$A$13,0), MATCH($D2, I_prop!$B$6:$H$6,0)) -> 0 | G2: =INDEX(I_prop!$B$18:$H$24, MATCH($C2, I_prop!$A$18:$A$24,0), MATCH($D2, I_prop!$B$17:$H$17,0)) -> 0 | H2: =IF($J2<>"",$J2,$F2) -> 0 | I2: =IF($K2<>"",$K2,$G2) -> 0 | J2: =IF(COUNTIFS(Subgroup_Overrides!$A$5:$A$200,"A",Subgroup_Overrides!$B$5:$B$200,$C2,Subgroup_Overrides!$C$5:$C$200,$D2)>0,_xludf.minifs(Subgroup_Overrides!$D$5:$D$200,Subgroup_Overrides!$A$5:$A$200,"A",Subgroup_Overrides!$B$5:$B$200,$C2,Subgroup_Overrides!$C$5:$C$200,$D2),"") | K2: =IF(COUNTIFS(Subgroup_Overrides!$A$5:$A$200,"B",Subgroup_Overrides!$B$5:$B$200,$C2,Subgroup_Overrides!$C$5:$C$200,$D2)>0,_xludf.minifs(Subgroup_Overrides!$D$5:$D$200,Subgroup_Overrides!$A$5:$A$200,"B",Subgroup_Overrides!$B$5:$B$200,$C2,Subgroup_Overrides!$C$5:$C$200,$D2),"") | L2: =TRIM(B2) -> LIFE | M2: =IF(H2="",NA(),1*H2) -> 0 | N2: =IF(I2="",NA(),1*I2) -> 0
A3: 2 | B3: LIFE | C3: U2 | D3: D2 | E3: -0.9 | F3: =INDEX(I_prop!$B$7:$H$13, MATCH($C3, I_prop!$A$7:$A$13,0), MATCH($D3, I_prop!$B$6:$H$6,0)) -> 0 | G3: =INDEX(I_prop!$B$18:$H$24, MATCH($C3, I_prop!$A$18:$A$24,0), MATCH($D3, I_prop!$B$17:$H$17,0)) -> 0 | H3: =IF($J3<>"",$J3,$F3) -> 0 | I3: =IF($K3<>"",$K3,$G3) -> 0 | J3: =IF(COUNTIFS(Subgroup_Overrides!$A$5:$A$200,"A",Subgroup_Overrides!$B$5:$B$200,$C3,Subgroup_Overrides!$C$5:$C$200,$D3)>0,_xludf.minifs(Subgroup_Overrides!$D$5:$D$200,Subgroup_Overrides!$A$5:$A$200,"A",Subgroup_Overrides!$B$5:$B$200,$C3,Subgroup_Overrides!$C$5:$C$200,$D3),"") | K3: =IF(COUNTIFS(Subgroup_Overrides!$A$5:$A$200,"B",Subgroup_Overrides!$B$5:$B$200,$C3,Subgroup_Overrides!$C$5:$C$200,$D3)>0,_xludf.minifs(Subgroup_Overrides!$D$5:$D$200,Subgroup_Overrides!$A$5:$A$200,"B",Subgroup_Overrides!$B$5:$B$200,$C3,Subgroup_Overrides!$C$5:$C$200,$D3),"") | L3: =TRIM(B3) -> LIFE | M3: =IF(H3="",NA(),1*H3) -> 0 | N3: =IF(I3="",NA(),1*I3) -> 0
A4: 3 | B4: LIFE | C4: U3 | D4: D2 | E4: -0.9 | F4: =INDEX(I_prop!$B$7:$H$13, MATCH($C4, I_prop!$A$7:$A$13,0), MATCH($D4, I_prop!$B$6:$H$6,0)) -> 0 | G4: =INDEX(I_prop!$B$18:$H$24, MATCH($C4, I_prop!$A$18:$A$24,0), MATCH($D4, I_prop!$B$17:$H$17,0)) -> 0 | H4: =IF($J4<>"",$J4,$F4) -> 0 | I4: =IF($K4<>"",$K4,$G4) -> 0 | J4: =IF(COUNTIFS(Subgroup_Overrides!$A$5:$A$200,"A",Subgroup_Overrides!$B$5:$B$200,$C4,Subgroup_Overrides!$C$5:$C$200,$D4)>0,_xludf.minifs(Subgroup_Overrides!$D$5:$D$200,Subgroup_Overrides!$A$5:$A$200,"A",Subgroup_Overrides!$B$5:$B$200,$C4,Subgroup_Overrides!$C$5:$C$200,$D4),"") | K4: =IF(COUNTIFS(Subgroup_Overrides!$A$5:$A$200,"B",Subgroup_Overrides!$B$5:$B$200,$C4,Subgroup_Overrides!$C$5:$C$200,$D4)>0,_xludf.minifs(Subgroup_Overrides!$D$5:$D$200,Subgroup_Overrides!$A$5:$A$200,"B",Subgroup_Overrides!$B$5:$B$200,$C4,Subgroup_Overrides!$C$5:$C$200,$D4),"") | L4: =TRIM(B4) -> LIFE | M4: =IF(H4="",NA(),1*H4) -> 0 | N4: =IF(I4="",NA(),1*I4) -> 0
A5: 4 | B5: LIFE | C5: U4 | D5: D2 | E5: -0.9 | F5: =INDEX(I_prop!$B$7:$H$13, MATCH($C5, I_prop!$A$7:$A$13,0), MATCH($D5, I_prop!$B$6:$H$6,0)) -> 0 | G5: =INDEX(I_prop!$B$18:$H$24, MATCH($C5, I_prop!$A$18:$A$24,0), MATCH($D5, I_prop!$B$17:$H$17,0)) -> 0 | H5: =IF($J5<>"",$J5,$F5) -> 0 | I5: =IF($K5<>"",$K5,$G5) -> 0 | J5: =IF(COUNTIFS(Subgroup_Overrides!$A$5:$A$200,"A",Subgroup_Overrides!$B$5:$B$200,$C5,Subgroup_Overrides!$C$5:$C$200,$D5)>0,_xludf.minifs(Subgroup_Overrides!$D$5:$D$200,Subgroup_Overrides!$A$5:$A$200,"A",Subgroup_Overrides!$B$5:$B$200,$C5,Subgroup_Overrides!$C$5:$C$200,$D5),"") | K5: =IF(COUNTIFS(Subgroup_Overrides!$A$5:$A$200,"B",Subgroup_Overrides!$B$5:$B$200,$C5,Subgroup_Overrides!$C$5:$C$200,$D5)>0,_xludf.minifs(Subgroup_Overrides!$D$5:$D$200,Subgroup_Overrides!$A$5:$A$200,"B",Subgroup_Overrides!$B$5:$B$200,$C5,Subgroup_Overrides!$C$5:$C$200,$D5),"") | L5: =TRIM(B5) -> LIFE | M5: =IF(H5="",NA(),1*H5) -> 0 | N5: =IF(I5="",NA(),1*I5) -> 0
A6: 5 | B6: LIFE | C6: U5 | D6: D2 | E6: -0.9 | F6: =INDEX(I_prop!$B$7:$H$13, MATCH($C6, I_prop!$A$7:$A$13,0), MATCH($D6, I_prop!$B$6:$H$6,0)) -> 0 | G6: =INDEX(I_prop!$B$18:$H$24, MATCH($C6, I_prop!$A$18:$A$24,0), MATCH($D6, I_prop!$B$17:$H$17,0)) -> 0 | H6: =IF($J6<>"",$J6,$F6) -> 0 | I6: =IF($K6<>"",$K6,$G6) -> 0 | J6: =IF(COUNTIFS(Subgroup_Overrides!$A$5:$A$200,"A",Subgroup_Overrides!$B$5:$B$200,$C6,Subgroup_Overrides!$C$5:$C$200,$D6)>0,_xludf.minifs(Subgroup_Overrides!$D$5:$D$200,Subgroup_Overrides!$A$5:$A$200,"A",Subgroup_Overrides!$B$5:$B$200,$C6,Subgroup_Overrides!$C$5:$C$200,$D6),"") | K6: =IF(COUNTIFS(Subgroup_Overrides!$A$5:$A$200,"B",Subgroup_Overrides!$B$5:$B$200,$C6,Subgroup_Overrides!$C$5:$C$200,$D6)>0,_xludf.minifs(Subgroup_Overrides!$D$5:$D$200,Subgroup_Overrides!$A$5:$A$200,"B",Subgroup_Overrides!$B$5:$B$200,$C6,Subgroup_Overrides!$C$5:$C$200,$D6),"") | L6: =TRIM(B6) -> LIFE | M6: =IF(H6="",NA(),1*H6) -> 0 | N6: =IF(I6="",NA(),1*I6) -> 0
A7: 6 | B7: LIFE | C7: U6 | D7: D2 | E7: -0.9 | F7: =INDEX(I_prop!$B$7:$H$13, MATCH($C7, I_prop!$A$7:$A$13,0), MATCH($D7, I_prop!$B$6:$H$6,0)) -> 0 | G7: =INDEX(I_prop!$B$18:$H$24, MATCH($C7, I_prop!$A$18:$A$24,0), MATCH($D7, I_prop!$B$17:$H$17,0)) -> 0 | H7: =IF($J7<>"",$J7,$F7) -> 0 | I7: =IF($K7<>"",$K7,$G7) -> 0 | J7: =IF(COUNTIFS(Subgroup_Overrides!$A$5:$A$200,"A",Subgroup_Overrides!$B$5:$B$200,$C7,Subgroup_Overrides!$C$5:$C$200,$D7)>0,_xludf.minifs(Subgroup_Overrides!$D$5:$D$200,Subgroup_Overrides!$A$5:$A$200,"A",Subgroup_Overrides!$B$5:$B$200,$C7,Subgroup_Overrides!$C$5:$C$200,$D7),"") | K7: =IF(COUNTIFS(Subgroup_Overrides!$A$5:$A$200,"B",Subgroup_Overrides!$B$5:$B$200,$C7,Subgroup_Overrides!$C$5:$C$200,$D7)>0,_xludf.minifs(Subgroup_Overrides!$D$5:$D$200,Subgroup_Overrides!$A$5:$A$200,"B",Subgroup_Overrides!$B$5:$B$200,$C7,Subgroup_Overrides!$C$5:$C$200,$D7),"") | L7: =TRIM(B7) -> LIFE | M7: =IF(H7="",NA(),1*H7) -> 0 | N7: =IF(I7="",NA(),1*I7) -> 0
A8: 7 | B8: LIFE | C8: U6 | D8: D7 | E8: -0.9 | F8: =INDEX(I_prop!$B$7:$H$13, MATCH($C8, I_prop!$A$7:$A$13,0), MATCH($D8, I_prop!$B$6:$H$6,0)) -> 0 | G8: =INDEX(I_prop!$B$18:$H$24, MATCH($C8, I_prop!$A$18:$A$24,0), MATCH($D8, I_prop!$B$17:$H$17,0)) -> 0 | H8: =IF($J8<>"",$J8,$F8) -> 0 | I8: =IF($K8<>"",$K8,$G8) -> 0 | J8: =IF(COUNTIFS(Subgroup_Overrides!$A$5:$A$200,"A",Subgroup_Overrides!$B$5:$B$200,$C8,Subgroup_Overrides!$C$5:$C$200,$D8)>0,_xludf.minifs(Subgroup_Overrides!$D$5:$D$200,Subgroup_Overrides!$A$5:$A$200,"A",Subgroup_Overrides!$B$5:$B$200,$C8,Subgroup_Overrides!$C$5:$C$200,$D8),"") | K8: =IF(COUNTIFS(Subgroup_Overrides!$A$5:$A$200,"B",Subgroup_Overrides!$B$5:$B$200,$C8,Subgroup_Overrides!$C$5:$C$200,$D8)>0,_xludf.minifs(Subgroup_Overrides!$D$5:$D$200,Subgroup_Overrides!$A$5:$A$200,"B",Subgroup_Overrides!$B$5:$B$200,$C8,Subgroup_Overrides!$C$5:$C$200,$D8),"") | L8: =TRIM(B8) -> LIFE | M8: =IF(H8="",NA(),1*H8) -> 0 | N8: =IF(I8="",NA(),1*I8) -> 0
A9: 8 | B9: BODY | C9: U1 | D9: D2 | E9: -0.7 | F9: =INDEX(I_prop!$B$7:$H$13, MATCH($C9, I_prop!$A$7:$A$13,0), MATCH($D9, I_prop!$B$6:$H$6,0)) -> 0 | G9: =INDEX(I_prop!$B$18:$H$24, MATCH($C9, I_prop!$A$18:$A$24,0), MATCH($D9, I_prop!$B$17:$H$17,0)) -> 0 | H9: =IF($J9<>"",$J9,$F9) -> 0 | I9: =IF($K9<>"",$K9,$G9) -> 0 | J9: =IF(COUNTIFS(Subgroup_Overrides!$A$5:$A$200,"A",Subgroup_Overrides!$B$5:$B$200,$C9,Subgroup_Overrides!$C$5:$C$200,$D9)>0,_xludf.minifs(Subgroup_Overrides!$D$5:$D$200,Subgroup_Overrides!$A$5:$A$200,"A",Subgroup_Overrides!$B$5:$B$200,$C9,Subgroup_Overrides!$C$5:$C$200,$D9),"") | K9: =IF(COUNTIFS(Subgroup_Overrides!$A$5:$A$200,"B",Subgroup_Overrides!$B$5:$B$200,$C9,Subgroup_Overrides!$C$5:$C$200,$D9)>0,_xludf.minifs(Subgroup_Overrides!$D$5:$D$200,Subgroup_Overrides!$A$5:$A$200,"B",Subgroup_Overrides!$B$5:$B$200,$C9,Subgroup_Overrides!$C$5:$C$200,$D9),"") | L9: =TRIM(B9) -> BODY | M9: =IF(H9="",NA(),1*H9) -> 0 | N9: =IF(I9="",NA(),1*I9) -> 0
A10: 9 | B10: BODY | C10: U2 | D10: D2 | E10: -0.7 | F10: =INDEX(I_prop!$B$7:$H$13, MATCH($C10, I_prop!$A$7:$A$13,0), MATCH($D10, I_prop!$B$6:$H$6,0)) -> 0 | G10: =INDEX(I_prop!$B$18:$H$24, MATCH($C10, I_prop!$A$18:$A$24,0), MATCH($D10, I_prop!$B$17:$H$17,0)) -> 0 | H10: =IF($J10<>"",$J10,$F10) -> 0 | I10: =IF($K10<>"",$K10,$G10) -> 0 | J10: =IF(COUNTIFS(Subgroup_Overrides!$A$5:$A$200,"A",Subgroup_Overrides!$B$5:$B$200,$C10,Subgroup_Overrides!$C$5:$C$200,$D10)>0,_xludf.minifs(Subgroup_Overrides!$D$5:$D$200,Subgroup_Overrides!$A$5:$A$200,"A",Subgroup_Overrides!$B$5:$B$200,$C10,Subgroup_Overrides!$C$5:$C$200,$D10),"") | K10: =IF(COUNTIFS(Subgroup_Overrides!$A$5:$A$200,"B",Subgroup_Overrides!$B$5:$B$200,$C10,Subgroup_Overrides!$C$5:$C$200,$D10)>0,_xludf.minifs(Subgroup_Overrides!$D$5:$D$200,Subgroup_Overrides!$A$5:$A$200,"B",Subgroup_Overrides!$B$5:$B$200,$C10,Subgroup_Overrides!$C$5:$C$200,$D10),"") | L10: =TRIM(B10) -> BODY | M10: =IF(H10="",NA(),1*H10) -> 0 | N10: =IF(I10="",NA(),1*I10) -> 0
A11: 10 | B11: BODY | C11: U3 | D11: D2 | E11: -0.7 | F11: =INDEX(I_prop!$B$7:$H$13, MATCH($C11, I_prop!$A$7:$A$13,0), MATCH($D11, I_prop!$B$6:$H$6,0)) -> 0 | G11: =INDEX(I_prop!$B$18:$H$24, MATCH($C11, I_prop!$A$18:$A$24,0), MATCH($D11, I_prop!$B$17:$H$17,0)) -> 0 | H11: =IF($J11<>"",$J11,$F11) -> 0 | I11: =IF($K11<>"",$K11,$G11) -> 0 | J11: =IF(COUNTIFS(Subgroup_Overrides!$A$5:$A$200,"A",Subgroup_Overrides!$B$5:$B$200,$C11,Subgroup_Overrides!$C$5:$C$200,$D11)>0,_xludf.minifs(Subgroup_Overrides!$D$5:$D$200,Subgroup_Overrides!$A$5:$A$200,"A",Subgroup_Overrides!$B$5:$B$200,$C11,Subgroup_Overrides!$C$5:$C$200,$D11),"") | K11: =IF(COUNTIFS(Subgroup_Overrides!$A$5:$A$200,"B",Subgroup_Overrides!$B$5:$B$200,$C11,Subgroup_Overrides!$C$5:$C$200,$D11)>0,_xludf.minifs(Subgroup_Overrides!$D$5:$D$200,Subgroup_Overrides!$A$5:$A$200,"B",Subgroup_Overrides!$B$5:$B$200,$C11,Subgroup_Overrides!$C$5:$C$200,$D11),"") | L11: =TRIM(B11) -> BODY | M11: =IF(H11="",NA(),1*H11) -> 0 | N11: =IF(I11="",NA(),1*I11) -> 0
A12: 11 | B12: BODY | C12: U4 | D12: D2 | E12: -0.7 | F12: =INDEX(I_prop!$B$7:$H$13, MATCH($C12, I_prop!$A$7:$A$13,0), MATCH($D12, I_prop!$B$6:$H$6,0)) -> 0 | G12: =INDEX(I_prop!$B$18:$H$24, MATCH($C12, I_prop!$A$18:$A$24,0), MATCH($D12, I_prop!$B$17:$H$17,0)) -> 0 | H12: =IF($J12<>"",$J12,$F12) -> 0 | I12: =IF($K12<>"",$K12,$G12) -> 0 | J12: =IF(COUNTIFS(Subgroup_Overrides!$A$5:$A$200,"A",Subgroup_Overrides!$B$5:$B$200,$C12,Subgroup_Overrides!$C$5:$C$200,$D12)>0,_xludf.minifs(Subgroup_Overrides!$D$5:$D$200,Subgroup_Overrides!$A$5:$A$200,"A",Subgroup_Overrides!$B$5:$B$200,$C12,Subgroup_Overrides!$C$5:$C$200,$D12),"") | K12: =IF(COUNTIFS(Subgroup_Overrides!$A$5:$A$200,"B",Subgroup_Overrides!$B$5:$B$200,$C12,Subgroup_Overrides!$C$5:$C$200,$D12)>0,_xludf.minifs(Subgroup_Overrides!$D$5:$D$200,Subgroup_Overrides!$A$5:$A$200,"B",Subgroup_Overrides!$B$5:$B$200,$C12,Subgroup_Overrides!$C$5:$C$200,$D12),"") | L12: =TRIM(B12) -> BODY | M12: =IF(H12="",NA(),1*H12) -> 0 | N12: =IF(I12="",NA(),1*I12) -> 0
A13: 12 | B13: BODY | C13: U5 | D13: D2 | E13: -0.7 | F13: =INDEX(I_prop!$B$7:$H$13, MATCH($C13, I_prop!$A$7:$A$13,0), MATCH($D13, I_prop!$B$6:$H$6,0)) -> 0 | G13: =INDEX(I_prop!$B$18:$H$24, MATCH($C13, I_prop!$A$18:$A$24,0), MATCH($D13, I_prop!$B$17:$H$17,0)) -> 0 | H13: =IF($J13<>"",$J13,$F13) -> 0 | I13: =IF($K13<>"",$K13,$G13) -> 0 | J13: =IF(COUNTIFS(Subgroup_Overrides!$A$5:$A$200,"A",Subgroup_Overrides!$B$5:$B$200,$C13,Subgroup_Overrides!$C$5:$C$200,$D13)>0,_xludf.minifs(Subgroup_Overrides!$D$5:$D$200,Subgroup_Overrides!$A$5:$A$200,"A",Subgroup_Overrides!$B$5:$B$200,$C13,Subgroup_Overrides!$C$5:$C$200,$D13),"") | K13: =IF(COUNTIFS(Subgroup_Overrides!$A$5:$A$200,"B",Subgroup_Overrides!$B$5:$B$200,$C13,Subgroup_Overrides!$C$5:$C$200,$D13)>0,_xludf.minifs(Subgroup_Overrides!$D$5:$D$200,Subgroup_Overrides!$A$5:$A$200,"B",Subgroup_Overrides!$B$5:$B$200,$C13,Subgroup_Overrides!$C$5:$C$200,$D13),"") | L13: =TRIM(B13) -> BODY | M13: =IF(H13="",NA(),1*H13) -> 0 | N13: =IF(I13="",NA(),1*I13) -> 0
... A71: 70 | B71: INFO | C71: U6 | D71: D5 | E71: -0.4 | F71: =INDEX(I_prop!$B$7:$H$13, MATCH($C71, I_prop!$A$7:$A$13,0), MATCH($D71, I_prop!$B$6:$H$6,0)) -> 0 | G71: =INDEX(I_prop!$B$18:$H$24, MATCH($C71, I_prop!$A$18:$A$24,0), MATCH($D71, I_prop!$B$17:$H$17,0)) -> 0 | H71: =IF($J71<>"",$J71,$F71) -> 0 | I71: =IF($K71<>"",$K71,$G71) -> 0 | J71: =IF(COUNTIFS(Subgroup_Overrides!$A$5:$A$200,"A",Subgroup_Overrides!$B$5:$B$200,$C71,Subgroup_Overrides!$C$5:$C$200,$D71)>0,_xludf.minifs(Subgroup_Overrides!$D$5:$D$200,Subgroup_Overrides!$A$5:$A$200,"A",Subgroup_Overrides!$B$5:$B$200,$C71,Subgroup_Overrides!$C$5:$C$200,$D71),"") | K71: =IF(COUNTIFS(Subgroup_Overrides!$A$5:$A$200,"B",Subgroup_Overrides!$B$5:$B$200,$C71,Subgroup_Overrides!$C$5:$C$200,$D71)>0,_xludf.minifs(Subgroup_Overrides!$D$5:$D$200,Subgroup_Overrides!$A$5:$A$200,"B",Subgroup_Overrides!$B$5:$B$200,$C71,Subgroup_Overrides!$C$5:$C$200,$D71),"") | L71: =TRIM(B71) -> INFO | M71: =IF(H71="",NA(),1*H71) -> 0 | N71: =IF(I71="",NA(),1*I71) -> 0

Sheet C_cat
A1: CATASTROPHE CELL SET (C_cat) - TRC Loss Computation
A3: Reference: Ripple_Logic v8.6 Section 8.3
A4: BASE SET (Canonical - governance approval required to extend)
A6: Cell | B6: Union | C6: Dimension | D6: Weight (ω_c) | E6: Rationale
A7: C1 | B7: U6 | C7: D2 (Health) | D7: 0.35 | E7: Humanity health catastrophe
A8: C2 | B8: U6 | C8: D7 (Environ) | D8: 0.3 | E8: Humanity-environment interface
A9: C3 | B9: U7 | C9: D7 (Environ) | D9: 0.35 | E9: Biosphere integrity
A11: Weight Sum Check: | B11: =SUM(D7:D9) -> 1 | C11: Must = 1.00
A13: EXTENSION GOVERNANCE
A14: Extended cells require:
A15: - Tier 3+ governance approval
A16: - Documentation in PCC
A17: - CCAT_EXTENDED flag set
A19: CCAT_EXTENDED Flag: | B19: NO - BASE ONLY

Sheet WTSL_Categories
A1: MANDATORY TAIL RISK CATEGORIES (WTSL)
A3: Reference: Ripple_Logic v8.6 Section 8.5
A4: Mandatory tails apply by default. WTSL-AIX is mandatory only if AI Deployment = YES. | D4: Included voluntarily (precautionary)
A6: Code | B6: Category | C6: Description | D6: p(cat) | E6: p_floor | F6: Status | G6: Required?
A7: WTSL-PAN | B7: Pandemic | C7: Global health crisis | D7: =SUMIF(Scenario_Impacts!$B$11:$B$16,A7,Scenario_Impacts!$C$11:$C$16) -> 0.08 | E7: 0.02 | F7: =IF(G7="NO","OPTIONAL",IF(D7>=E7,"✓ COVERED","✗ MISSING")) -> ✓ COVERED | G7: =IF(A7="WTSL-AIX",IF(Config!$B$13="YES","YES","NO"),"YES") -> YES
A8: WTSL-CLI | B8: Climate | C8: Climate catastrophe | D8: =SUMIF(Scenario_Impacts!$B$11:$B$16,A8,Scenario_Impacts!$C$11:$C$16) -> 0.07 | E8: 0.02 | F8: =IF(G8="NO","OPTIONAL",IF(D8>=E8,"✓ COVERED","✗ MISSING")) -> ✓ COVERED | G8: =IF(A8="WTSL-AIX",IF(Config!$B$13="YES","YES","NO"),"YES") -> YES
A9: WTSL-FIN | B9: Financial | C9: Financial system collapse | D9: =SUMIF(Scenario_Impacts!$B$11:$B$16,A9,Scenario_Impacts!$C$11:$C$16) -> 0.15 | E9: 0.02 | F9: =IF(G9="NO","OPTIONAL",IF(D9>=E9,"✓ COVERED","✗ MISSING")) -> ✓ COVERED | G9: =IF(A9="WTSL-AIX",IF(Config!$B$13="YES","YES","NO"),"YES") -> YES
A10: WTSL-CON | B10: Conflict | C10: Major armed conflict | D10: =SUMIF(Scenario_Impacts!$B$11:$B$16,A10,Scenario_Impacts!$C$11:$C$16) -> 0.03 | E10: 0.02 | F10: =IF(G10="NO","OPTIONAL",IF(D10>=E10,"✓ COVERED","✗ MISSING")) -> ✓ COVERED | G10: =IF(A10="WTSL-AIX",IF(Config!$B$13="YES","YES","NO"),"YES") -> YES
A11: WTSL-INF | B11: Infrastructure | C11: Critical infrastructure failure | D11: =SUMIF(Scenario_Impacts!$B$11:$B$16,A11,Scenario_Impacts!$C$11:$C$16) -> 0.05 | E11: 0.02 | F11: =IF(G11="NO","OPTIONAL",IF(D11>=E11,"✓ COVERED","✗ MISSING")) -> ✓ COVERED | G11: =IF(A11="WTSL-AIX",IF(Config!$B$13="YES","YES","NO"),"YES") -> YES
A12: WTSL-AIX | B12: AI Risk | C12: AI misalignment event | D12: =SUMIF(Scenario_Impacts!$B$11:$B$16,A12,Scenario_Impacts!$C$11:$C$16) -> 0.02 | E12: 0.02 | F12: =IF(G12="NO","OPTIONAL",IF(D12>=E12,"✓ COVERED","✗ MISSING")) -> OPTIONAL | G12: =IF(A12="WTSL-AIX",IF(Config!$B$13="YES","YES","NO"),"YES") -> NO
A15: COVERAGE CHECK
A16: Mandatory Count: | B16: =CANON!B41 -> 5 | C16: (5 if AI_DEPLOYMENT=NO, 6 if YES)
A17: Covered Count: | B17: =COUNTIF(F7:F12,"✓*") -> 5
A18: Probability Sum: | B18: =SUM(D7:D12) -> 0.4 | C18: (tail scenarios; baseline = 0.60)

Sheet Impact_Input
A1: IMPACT INSTANCE INPUT
A3: Formula: Contribution = μ × r × ℓ × c × e × s × τ(t)
A4: τ(t) = MIN(1, LN(1+MAX(t, t_min)) / LN(1+T_ref)) where T_ref=25, t_min=0.083 [v8.6 Appendix B.1]
A6: ID | B6: Opt | C6: Union | D6: Dim | E6: Description | F6: μ | G6: r | H6: ℓ | I6: c | J6: t | K6: e | L6: s | M6: τ(t) | N6: Contrib
A7: I01 | B7: A | C7: U3 | D7: D3 | E7: Reduced in-person interaction | F7: -0.3 | G7: 0.8 | H7: 0.7 | I7: 0.5 | J7: 5 | K7: 1 | L7: 1 | M7: =MIN(1, LN(1+MAX(J7, CANON!$B$27)) / LN(1+CANON!$B$25)) -> 0.54994057 | N7: =F7*G7*H7*I7*K7*L7*M7 -> -0.046195008
A8: I02 | B8: A | C8: U3 | D8: D3 | E8: Increased online community | F8: 0.15 | G8: 0.6 | H8: 0.5 | I8: 0.3 | J8: 3 | K8: 1 | L8: 1 | M8: =MIN(1, LN(1+MAX(J8, CANON!$B$27)) / LN(1+CANON!$B$25)) -> 0.42549211 | N8: =F8*G8*H8*I8*K8*L8*M8 -> 0.0057441434
A9: I03 | B9: A | C9: U1 | D9: D5 | E9: Increased work flexibility | F9: 0.4 | G9: 0.9 | H9: 0.8 | I9: 0.6 | J9: 10 | K9: 1 | L9: 1 | M9: =MIN(1, LN(1+MAX(J9, CANON!$B$27)) / LN(1+CANON!$B$25)) -> 0.73598042 | N9: =F9*G9*H9*I9*K9*L9*M9 -> 0.12717742
A10: I04 | B10: A | C10: U2 | D10: D1 | E10: Reduced commuting costs | F10: 0.25 | G10: 0.7 | H10: 0.6 | I10: 0.4 | J10: 5 | K10: 1 | L10: 1 | M10: =MIN(1, LN(1+MAX(J10, CANON!$B$27)) / LN(1+CANON!$B$25)) -> 0.54994057 | N10: =F10*G10*H10*I10*K10*L10*M10 -> 0.023097504
A11: I05 | B11: A | C11: U1 | D11: D6 | E11: Better work-life balance | F11: 0.35 | G11: 0.8 | H11: 0.7 | I11: 0.5 | J11: 10 | K11: 1 | L11: 1 | M11: =MIN(1, LN(1+MAX(J11, CANON!$B$27)) / LN(1+CANON!$B$25)) -> 0.73598042 | N11: =F11*G11*H11*I11*K11*L11*M11 -> 0.072126082
A12: I06 | B12: A | C12: U7 | D12: D7 | E12: Reduced carbon emissions | F12: 0.15 | G12: 0.5 | H12: 0.4 | I12: 0.3 | J12: 15 | K12: 1 | L12: 1 | M12: =MIN(1, LN(1+MAX(J12, CANON!$B$27)) / LN(1+CANON!$B$25)) -> 0.85098421 | N12: =F12*G12*H12*I12*K12*L12*M12 -> 0.0076588579
A13: I07 | B13: A | C13: U4 | D13: D1 | E13: Tech infrastructure costs | F13: -0.2 | G13: 0.9 | H13: 0.8 | I13: 0.7 | J13: 3 | K13: 1 | L13: 1 | M13: =MIN(1, LN(1+MAX(J13, CANON!$B$27)) / LN(1+CANON!$B$25)) -> 0.42549211 | N13: =F13*G13*H13*I13*K13*L13*M13 -> -0.042889604
A14: I08 | B14: A | C14: U3 | D14: D1 | E14: Reduced local business revenue | F14: -0.15 | G14: 0.6 | H14: 0.5 | I14: 0.4 | J14: 5 | K14: 1 | L14: 1 | M14: =MIN(1, LN(1+MAX(J14, CANON!$B$27)) / LN(1+CANON!$B$25)) -> 0.54994057 | N14: =F14*G14*H14*I14*K14*L14*M14 -> -0.0098989303
A15: I09 | B15: B | C15: U3 | D15: D3 | E15: Maintained in-person bonds | F15: 0.2 | G15: 0.8 | H15: 0.7 | I15: 0.5 | J15: 5 | K15: 1 | L15: 1 | M15: =MIN(1, LN(1+MAX(J15, CANON!$B$27)) / LN(1+CANON!$B$25)) -> 0.54994057 | N15: =F15*G15*H15*I15*K15*L15*M15 -> 0.030796672
A16: I10 | B16: B | C16: U1 | D16: D5 | E16: Limited flexibility | F16: -0.15 | G16: 0.7 | H16: 0.6 | I16: 0.5 | J16: 10 | K16: 1 | L16: 1 | M16: =MIN(1, LN(1+MAX(J16, CANON!$B$27)) / LN(1+CANON!$B$25)) -> 0.73598042 | N16: =F16*G16*H16*I16*K16*L16*M16 -> -0.023183383
A17: I11 | B17: B | C17: U2 | D17: D1 | E17: Continued commuting costs | F17: -0.1 | G17: 0.7 | H17: 0.6 | I17: 0.4 | J17: 5 | K17: 1 | L17: 1 | M17: =MIN(1, LN(1+MAX(J17, CANON!$B$27)) / LN(1+CANON!$B$25)) -> 0.54994057 | N17: =F17*G17*H17*I17*K17*L17*M17 -> -0.0092390016
A18: I12 | B18: B | C18: U7 | D18: D7 | E18: Continued emissions | F18: -0.1 | G18: 0.5 | H18: 0.4 | I18: 0.3 | J18: 15 | K18: 1 | L18: 1 | M18: =MIN(1, LN(1+MAX(J18, CANON!$B$27)) / LN(1+CANON!$B$25)) -> 0.85098421 | N18: =F18*G18*H18*I18*K18*L18*M18 -> -0.0051059053
... A20: I14 | B20: B | C20: U3 | D20: D1 | E20: Maintained local business | F20: 0.1 | G20: 0.6 | H20: 0.5 | I20: 0.4 | J20: 5 | K20: 1 | L20: 1 | M20: =MIN(1, LN(1+MAX(J20, CANON!$B$27)) / LN(1+CANON!$B$25)) -> 0.54994057 | N20: =F20*G20*H20*I20*K20*L20*M20 -> 0.0065992868

Sheet Scenario_Impacts
A1: SCENARIO-CONDITIONED IMPACT TABLES
A3: Reference: Ripple_Logic v8.6 Section 8.4
A4: L(a,s) = Σ_{c∈C_cat} ω_c × max(0, −I_prop_c(a|s))
A5: NOTE: Loss is computed from catastrophe-cell impacts. Do NOT manually enter Loss. Fill catastrophe-cell impacts (F:H) per scenario; Loss (computed) updates automatically.
A6: C_cat: U6-D2(0.35), U6-D7(0.30), U7-D7(0.35)
A8: OPTION A SCENARIO LOSSES
A9: Scenario | B9: Category | C9: p(s) | D9: Loss | E9: Pathway | F9: U6-D2 I_prop | G9: U6-D7 I_prop | H9: U7-D7 I_prop | I9: Loss (computed)
A10: S01 | B10: BASELINE | C10: 0.6 | D10: =I10 -> 0 | E10: Minor monitoring reduction | F10: 0 | G10: 0 | H10: 0.015317 | I10: =0.35*MAX(0,-F10)+0.3*MAX(0,-G10)+0.35*MAX(0,-H10) -> 0
A11: S02 | B11: WTSL-FIN | C11: 0.15 | D11: =I11 -> 0.007 | E11: Budget cuts reduce compliance | F11: -0.02 | G11: 0 | H11: 0.01 | I11: =0.35*MAX(0,-F11)+0.3*MAX(0,-G11)+0.35*MAX(0,-H11) -> 0.007
A12: S03 | B12: WTSL-PAN | C12: 0.08 | D12: =I12 -> 0.0175 | E12: Health crisis, isolation stress | F12: -0.05 | G12: 0 | H12: 0.02 | I12: =0.35*MAX(0,-F12)+0.3*MAX(0,-G12)+0.35*MAX(0,-H12) -> 0.0175
A13: S04 | B13: WTSL-CLI | C13: 0.07 | D13: =I13 -> 0.0195 | E13: Climate degrades biosphere | F13: -0.01 | G13: -0.03 | H13: -0.02 | I13: =0.35*MAX(0,-F13)+0.3*MAX(0,-G13)+0.35*MAX(0,-H13) -> 0.0195
A14: S05 | B14: WTSL-INF | C14: 0.05 | D14: =I14 -> 0.0135 | E14: Tech dependency vulnerability | F14: -0.03 | G14: -0.01 | H14: 0.01 | I14: =0.35*MAX(0,-F14)+0.3*MAX(0,-G14)+0.35*MAX(0,-H14) -> 0.0135
A15: S06 | B15: WTSL-CON | C15: 0.03 | D15: =I15 -> 0.0235 | E15: Conflict casualties | F15: -0.04 | G15: -0.02 | H15: -0.01 | I15: =0.35*MAX(0,-F15)+0.3*MAX(0,-G15)+0.35*MAX(0,-H15) -> 0.0235
A16: S07 | B16: WTSL-AIX | C16: 0.02 | D16: =I16 -> 0.01 | E16: AI failures cascade | F16: -0.02 | G16: -0.01 | H16: 0 | I16: =0.35*MAX(0,-F16)+0.3*MAX(0,-G16)+0.35*MAX(0,-H16) -> 0.01
A19: OPTION B SCENARIO LOSSES
A20: Scenario | B20: Category | C20: p(s) | D20: Loss | E20: Pathway | F20: U6-D2 I_prop | G20: U6-D7 I_prop | H20: U7-D7 I_prop | I20: Loss (computed)
A21: S01 | B21: BASELINE | C21: 0.6 | D21: =I21 -> 0.00357385 | E21: Emissions continue | F21: 0 | G21: 0 | H21: -0.010211 | I21: =0.35*MAX(0,-F21)+0.3*MAX(0,-G21)+0.35*MAX(0,-H21) -> 0.00357385
A22: S02 | B22: WTSL-FIN | C22: 0.15 | D22: =I22 -> 0.0105 | E22: Community bonds buffer | F22: -0.015 | G22: 0 | H22: -0.015 | I22: =0.35*MAX(0,-F22)+0.3*MAX(0,-G22)+0.35*MAX(0,-H22) -> 0.0105
A23: S03 | B23: WTSL-PAN | C23: 0.08 | D23: =I23 -> 0.0315 | E23: Transmission risk | F23: -0.08 | G23: 0 | H23: -0.01 | I23: =0.35*MAX(0,-F23)+0.3*MAX(0,-G23)+0.35*MAX(0,-H23) -> 0.0315
A24: S04 | B24: WTSL-CLI | C24: 0.07 | D24: =I24 -> 0.0235 | E24: Resilience buffers | F24: -0.01 | G24: -0.02 | H24: -0.04 | I24: =0.35*MAX(0,-F24)+0.3*MAX(0,-G24)+0.35*MAX(0,-H24) -> 0.0235
A25: S05 | B25: WTSL-INF | C25: 0.05 | D25: =I25 -> 0.0135 | E25: Less tech-dependent | F25: -0.02 | G25: -0.01 | H25: -0.01 | I25: =0.35*MAX(0,-F25)+0.3*MAX(0,-G25)+0.35*MAX(0,-H25) -> 0.0135
A26: S06 | B26: WTSL-CON | C26: 0.03 | D26: =I26 -> 0.02175 | E26: Human coord persists | F26: -0.03 | G26: -0.02 | H26: -0.015 | I26: =0.35*MAX(0,-F26)+0.3*MAX(0,-G26)+0.35*MAX(0,-H26) -> 0.02175
A27: S07 | B27: WTSL-AIX | C27: 0.02 | D27: =I27 -> 0.007 | E27: Less AI dependency | F27: -0.01 | G27: 0 | H27: -0.01 | I27: =0.35*MAX(0,-F27)+0.3*MAX(0,-G27)+0.35*MAX(0,-H27) -> 0.007
A29: KEY INSIGHT: Option A has 0 catastrophic loss; Option B has minor loss (0.003574) in baseline
A30: Both options pass TRC (CVaR ≤ τ_TRC = 0.20)
A31: NOTE: WTSL-AIX (S07) included voluntarily as precautionary measure. | B31: AI_DEPLOYMENT=NO, so not mandatory for tail coverage.

Sheet I_prop
A1: IMPACT PROPAGATION MATRIX (I_prop)
A3: Mode: NONE (direct aggregation from Impact_Input; post-saturation tanh(β×Ĩ_dir))
A5: OPTION A
B6: D1 | C6: D2 | D6: D3 | E6: D4 | F6: D5 | G6: D6 | H6: D7
A7: U1 | B7: =TANH(Parameters!$B$24*SUMIFS(Impact_Input!$N:$N,Impact_Input!$B:$B,"A",Impact_Input!$C:$C,$A7,Impact_Input!$D:$D,B$6)) -> 0 | C7: =TANH(Parameters!$B$24*SUMIFS(Impact_Input!$N:$N,Impact_Input!$B:$B,"A",Impact_Input!$C:$C,$A7,Impact_Input!$D:$D,C$6)) -> 0 | D7: =TANH(Parameters!$B$24*SUMIFS(Impact_Input!$N:$N,Impact_Input!$B:$B,"A",Impact_Input!$C:$C,$A7,Impact_Input!$D:$D,D$6)) -> 0 | E7: =TANH(Parameters!$B$24*SUMIFS(Impact_Input!$N:$N,Impact_Input!$B:$B,"A",Impact_Input!$C:$C,$A7,Impact_Input!$D:$D,E$6)) -> 0 | F7: =TANH(Parameters!$B$24*SUMIFS(Impact_Input!$N:$N,Impact_Input!$B:$B,"A",Impact_Input!$C:$C,$A7,Impact_Input!$D:$D,F$6)) -> 0.24900788 | G7: =TANH(Parameters!$B$24*SUMIFS(Impact_Input!$N:$N,Impact_Input!$B:$B,"A",Impact_Input!$C:$C,$A7,Impact_Input!$D:$D,G$6)) -> 0.14325986 | H7: =TANH(Parameters!$B$24*SUMIFS(Impact_Input!$N:$N,Impact_Input!$B:$B,"A",Impact_Input!$C:$C,$A7,Impact_Input!$D:$D,H$6)) -> 0
A8: U2 | B8: =TANH(Parameters!$B$24*SUMIFS(Impact_Input!$N:$N,Impact_Input!$B:$B,"A",Impact_Input!$C:$C,$A8,Impact_Input!$D:$D,B$6)) -> 0.046162176 | C8: =TANH(Parameters!$B$24*SUMIFS(Impact_Input!$N:$N,Impact_Input!$B:$B,"A",Impact_Input!$C:$C,$A8,Impact_Input!$D:$D,C$6)) -> 0 | D8: =TANH(Parameters!$B$24*SUMIFS(Impact_Input!$N:$N,Impact_Input!$B:$B,"A",Impact_Input!$C:$C,$A8,Impact_Input!$D:$D,D$6)) -> 0 | E8: =TANH(Parameters!$B$24*SUMIFS(Impact_Input!$N:$N,Impact_Input!$B:$B,"A",Impact_Input!$C:$C,$A8,Impact_Input!$D:$D,E$6)) -> 0 | F8: =TANH(Parameters!$B$24*SUMIFS(Impact_Input!$N:$N,Impact_Input!$B:$B,"A",Impact_Input!$C:$C,$A8,Impact_Input!$D:$D,F$6)) -> 0 | G8: =TANH(Parameters!$B$24*SUMIFS(Impact_Input!$N:$N,Impact_Input!$B:$B,"A",Impact_Input!$C:$C,$A8,Impact_Input!$D:$D,G$6)) -> 0 | H8: =TANH(Parameters!$B$24*SUMIFS(Impact_Input!$N:$N,Impact_Input!$B:$B,"A",Impact_Input!$C:$C,$A8,Impact_Input!$D:$D,H$6)) -> 0
A9: U3 | B9: =TANH(Parameters!$B$24*SUMIFS(Impact_Input!$N:$N,Impact_Input!$B:$B,"A",Impact_Input!$C:$C,$A9,Impact_Input!$D:$D,B$6)) -> -0.019795274 | C9: =TANH(Parameters!$B$24*SUMIFS(Impact_Input!$N:$N,Impact_Input!$B:$B,"A",Impact_Input!$C:$C,$A9,Impact_Input!$D:$D,C$6)) -> 0 | D9: =TANH(Parameters!$B$24*SUMIFS(Impact_Input!$N:$N,Impact_Input!$B:$B,"A",Impact_Input!$C:$C,$A9,Impact_Input!$D:$D,D$6)) -> -0.080725687 | E9: =TANH(Parameters!$B$24*SUMIFS(Impact_Input!$N:$N,Impact_Input!$B:$B,"A",Impact_Input!$C:$C,$A9,Impact_Input!$D:$D,E$6)) -> 0 | F9: =TANH(Parameters!$B$24*SUMIFS(Impact_Input!$N:$N,Impact_Input!$B:$B,"A",Impact_Input!$C:$C,$A9,Impact_Input!$D:$D,F$6)) -> 0 | G9: =TANH(Parameters!$B$24*SUMIFS(Impact_Input!$N:$N,Impact_Input!$B:$B,"A",Impact_Input!$C:$C,$A9,Impact_Input!$D:$D,G$6)) -> 0 | H9: =TANH(Parameters!$B$24*SUMIFS(Impact_Input!$N:$N,Impact_Input!$B:$B,"A",Impact_Input!$C:$C,$A9,Impact_Input!$D:$D,H$6)) -> 0
A10: U4 | B10: =TANH(Parameters!$B$24*SUMIFS(Impact_Input!$N:$N,Impact_Input!$B:$B,"A",Impact_Input!$C:$C,$A10,Impact_Input!$D:$D,B$6)) -> -0.085569436 | C10: =TANH(Parameters!$B$24*SUMIFS(Impact_Input!$N:$N,Impact_Input!$B:$B,"A",Impact_Input!$C:$C,$A10,Impact_Input!$D:$D,C$6)) -> 0 | D10: =TANH(Parameters!$B$24*SUMIFS(Impact_Input!$N:$N,Impact_Input!$B:$B,"A",Impact_Input!$C:$C,$A10,Impact_Input!$D:$D,D$6)) -> 0 | E10: =TANH(Parameters!$B$24*SUMIFS(Impact_Input!$N:$N,Impact_Input!$B:$B,"A",Impact_Input!$C:$C,$A10,Impact_Input!$D:$D,E$6)) -> 0 | F10: =TANH(Parameters!$B$24*SUMIFS(Impact_Input!$N:$N,Impact_Input!$B:$B,"A",Impact_Input!$C:$C,$A10,Impact_Input!$D:$D,F$6)) -> 0 | G10: =TANH(Parameters!$B$24*SUMIFS(Impact_Input!$N:$N,Impact_Input!$B:$B,"A",Impact_Input!$C:$C,$A10,Impact_Input!$D:$D,G$6)) -> 0 | H10: =TANH(Parameters!$B$24*SUMIFS(Impact_Input!$N:$N,Impact_Input!$B:$B,"A",Impact_Input!$C:$C,$A10,Impact_Input!$D:$D,H$6)) -> 0
A11: U5 | B11: =TANH(Parameters!$B$24*SUMIFS(Impact_Input!$N:$N,Impact_Input!$B:$B,"A",Impact_Input!$C:$C,$A11,Impact_Input!$D:$D,B$6)) -> 0 | C11: =TANH(Parameters!$B$24*SUMIFS(Impact_Input!$N:$N,Impact_Input!$B:$B,"A",Impact_Input!$C:$C,$A11,Impact_Input!$D:$D,C$6)) -> 0 | D11: =TANH(Parameters!$B$24*SUMIFS(Impact_Input!$N:$N,Impact_Input!$B:$B,"A",Impact_Input!$C:$C,$A11,Impact_Input!$D:$D,D$6)) -> 0 | E11: =TANH(Parameters!$B$24*SUMIFS(Impact_Input!$N:$N,Impact_Input!$B:$B,"A",Impact_Input!$C:$C,$A11,Impact_Input!$D:$D,E$6)) -> 0 | F11: =TANH(Parameters!$B$24*SUMIFS(Impact_Input!$N:$N,Impact_Input!$B:$B,"A",Impact_Input!$C:$C,$A11,Impact_Input!$D:$D,F$6)) -> 0 | G11: =TANH(Parameters!$B$24*SUMIFS(Impact_Input!$N:$N,Impact_Input!$B:$B,"A",Impact_Input!$C:$C,$A11,Impact_Input!$D:$D,G$6)) -> 0 | H11: =TANH(Parameters!$B$24*SUMIFS(Impact_Input!$N:$N,Impact_Input!$B:$B,"A",Impact_Input!$C:$C,$A11,Impact_Input!$D:$D,H$6)) -> 0
A12: U6 | B12: =TANH(Parameters!$B$24*SUMIFS(Impact_Input!$N:$N,Impact_Input!$B:$B,"A",Impact_Input!$C:$C,$A12,Impact_Input!$D:$D,B$6)) -> 0 | C12: =TANH(Parameters!$B$24*SUMIFS(Impact_Input!$N:$N,Impact_Input!$B:$B,"A",Impact_Input!$C:$C,$A12,Impact_Input!$D:$D,C$6)) -> 0 | D12: =TANH(Parameters!$B$24*SUMIFS(Impact_Input!$N:$N,Impact_Input!$B:$B,"A",Impact_Input!$C:$C,$A12,Impact_Input!$D:$D,D$6)) -> 0 | E12: =TANH(Parameters!$B$24*SUMIFS(Impact_Input!$N:$N,Impact_Input!$B:$B,"A",Impact_Input!$C:$C,$A12,Impact_Input!$D:$D,E$6)) -> 0 | F12: =TANH(Parameters!$B$24*SUMIFS(Impact_Input!$N:$N,Impact_Input!$B:$B,"A",Impact_Input!$C:$C,$A12,Impact_Input!$D:$D,F$6)) -> 0 | G12: =TANH(Parameters!$B$24*SUMIFS(Impact_Input!$N:$N,Impact_Input!$B:$B,"A",Impact_Input!$C:$C,$A12,Impact_Input!$D:$D,G$6)) -> 0 | H12: =TANH(Parameters!$B$24*SUMIFS(Impact_Input!$N:$N,Impact_Input!$B:$B,"A",Impact_Input!$C:$C,$A12,Impact_Input!$D:$D,H$6)) -> 0
A13: U7 | B13: =TANH(Parameters!$B$24*SUMIFS(Impact_Input!$N:$N,Impact_Input!$B:$B,"A",Impact_Input!$C:$C,$A13,Impact_Input!$D:$D,B$6)) -> 0 | C13: =TANH(Parameters!$B$24*SUMIFS(Impact_Input!$N:$N,Impact_Input!$B:$B,"A",Impact_Input!$C:$C,$A13,Impact_Input!$D:$D,C$6)) -> 0 | D13: =TANH(Parameters!$B$24*SUMIFS(Impact_Input!$N:$N,Impact_Input!$B:$B,"A",Impact_Input!$C:$C,$A13,Impact_Input!$D:$D,D$6)) -> 0 | E13: =TANH(Parameters!$B$24*SUMIFS(Impact_Input!$N:$N,Impact_Input!$B:$B,"A",Impact_Input!$C:$C,$A13,Impact_Input!$D:$D,E$6)) -> 0 | F13: =TANH(Parameters!$B$24*SUMIFS(Impact_Input!$N:$N,Impact_Input!$B:$B,"A",Impact_Input!$C:$C,$A13,Impact_Input!$D:$D,F$6)) -> 0 | G13: =TANH(Parameters!$B$24*SUMIFS(Impact_Input!$N:$N,Impact_Input!$B:$B,"A",Impact_Input!$C:$C,$A13,Impact_Input!$D:$D,G$6)) -> 0 | H13: =TANH(Parameters!$B$24*SUMIFS(Impact_Input!$N:$N,Impact_Input!$B:$B,"A",Impact_Input!$C:$C,$A13,Impact_Input!$D:$D,H$6)) -> 0.015316518
A16: OPTION B
B17: D1 | C17: D2 | D17: D3 | E17: D4 | F17: D5 | G17: D6 | H17: D7
A18: U1 | B18: =TANH(Parameters!$B$24*SUMIFS(Impact_Input!$N:$N,Impact_Input!$B:$B,"B",Impact_Input!$C:$C,$A18,Impact_Input!$D:$D,B$17)) -> 0 | C18: =TANH(Parameters!$B$24*SUMIFS(Impact_Input!$N:$N,Impact_Input!$B:$B,"B",Impact_Input!$C:$C,$A18,Impact_Input!$D:$D,C$17)) -> 0 | D18: =TANH(Parameters!$B$24*SUMIFS(Impact_Input!$N:$N,Impact_Input!$B:$B,"B",Impact_Input!$C:$C,$A18,Impact_Input!$D:$D,D$17)) -> 0 | E18: =TANH(Parameters!$B$24*SUMIFS(Impact_Input!$N:$N,Impact_Input!$B:$B,"B",Impact_Input!$C:$C,$A18,Impact_Input!$D:$D,E$17)) -> 0 | F18: =TANH(Parameters!$B$24*SUMIFS(Impact_Input!$N:$N,Impact_Input!$B:$B,"B",Impact_Input!$C:$C,$A18,Impact_Input!$D:$D,F$17)) -> -0.046333568 | G18: =TANH(Parameters!$B$24*SUMIFS(Impact_Input!$N:$N,Impact_Input!$B:$B,"B",Impact_Input!$C:$C,$A18,Impact_Input!$D:$D,G$17)) -> 0 | H18: =TANH(Parameters!$B$24*SUMIFS(Impact_Input!$N:$N,Impact_Input!$B:$B,"B",Impact_Input!$C:$C,$A18,Impact_Input!$D:$D,H$17)) -> 0
A19: U2 | B19: =TANH(Parameters!$B$24*SUMIFS(Impact_Input!$N:$N,Impact_Input!$B:$B,"B",Impact_Input!$C:$C,$A19,Impact_Input!$D:$D,B$17)) -> -0.0184759 | C19: =TANH(Parameters!$B$24*SUMIFS(Impact_Input!$N:$N,Impact_Input!$B:$B,"B",Impact_Input!$C:$C,$A19,Impact_Input!$D:$D,C$17)) -> 0 | D19: =TANH(Parameters!$B$24*SUMIFS(Impact_Input!$N:$N,Impact_Input!$B:$B,"B",Impact_Input!$C:$C,$A19,Impact_Input!$D:$D,D$17)) -> 0 | E19: =TANH(Parameters!$B$24*SUMIFS(Impact_Input!$N:$N,Impact_Input!$B:$B,"B",Impact_Input!$C:$C,$A19,Impact_Input!$D:$D,E$17)) -> 0 | F19: =TANH(Parameters!$B$24*SUMIFS(Impact_Input!$N:$N,Impact_Input!$B:$B,"B",Impact_Input!$C:$C,$A19,Impact_Input!$D:$D,F$17)) -> 0 | G19: =TANH(Parameters!$B$24*SUMIFS(Impact_Input!$N:$N,Impact_Input!$B:$B,"B",Impact_Input!$C:$C,$A19,Impact_Input!$D:$D,G$17)) -> 0 | H19: =TANH(Parameters!$B$24*SUMIFS(Impact_Input!$N:$N,Impact_Input!$B:$B,"B",Impact_Input!$C:$C,$A19,Impact_Input!$D:$D,H$17)) -> 0
A20: U3 | B20: =TANH(Parameters!$B$24*SUMIFS(Impact_Input!$N:$N,Impact_Input!$B:$B,"B",Impact_Input!$C:$C,$A20,Impact_Input!$D:$D,B$17)) -> 0.013197807 | C20: =TANH(Parameters!$B$24*SUMIFS(Impact_Input!$N:$N,Impact_Input!$B:$B,"B",Impact_Input!$C:$C,$A20,Impact_Input!$D:$D,C$17)) -> 0 | D20: =TANH(Parameters!$B$24*SUMIFS(Impact_Input!$N:$N,Impact_Input!$B:$B,"B",Impact_Input!$C:$C,$A20,Impact_Input!$D:$D,D$17)) -> 0.061515572 | E20: =TANH(Parameters!$B$24*SUMIFS(Impact_Input!$N:$N,Impact_Input!$B:$B,"B",Impact_Input!$C:$C,$A20,Impact_Input!$D:$D,E$17)) -> 0 | F20: =TANH(Parameters!$B$24*SUMIFS(Impact_Input!$N:$N,Impact_Input!$B:$B,"B",Impact_Input!$C:$C,$A20,Impact_Input!$D:$D,F$17)) -> 0 | G20: =TANH(Parameters!$B$24*SUMIFS(Impact_Input!$N:$N,Impact_Input!$B:$B,"B",Impact_Input!$C:$C,$A20,Impact_Input!$D:$D,G$17)) -> 0 | H20: =TANH(Parameters!$B$24*SUMIFS(Impact_Input!$N:$N,Impact_Input!$B:$B,"B",Impact_Input!$C:$C,$A20,Impact_Input!$D:$D,H$17)) -> 0
A21: U4 | B21: =TANH(Parameters!$B$24*SUMIFS(Impact_Input!$N:$N,Impact_Input!$B:$B,"B",Impact_Input!$C:$C,$A21,Impact_Input!$D:$D,B$17)) -> 0.010211456 | C21: =TANH(Parameters!$B$24*SUMIFS(Impact_Input!$N:$N,Impact_Input!$B:$B,"B",Impact_Input!$C:$C,$A21,Impact_Input!$D:$D,C$17)) -> 0 | D21: =TANH(Parameters!$B$24*SUMIFS(Impact_Input!$N:$N,Impact_Input!$B:$B,"B",Impact_Input!$C:$C,$A21,Impact_Input!$D:$D,D$17)) -> 0 | E21: =TANH(Parameters!$B$24*SUMIFS(Impact_Input!$N:$N,Impact_Input!$B:$B,"B",Impact_Input!$C:$C,$A21,Impact_Input!$D:$D,E$17)) -> 0 | F21: =TANH(Parameters!$B$24*SUMIFS(Impact_Input!$N:$N,Impact_Input!$B:$B,"B",Impact_Input!$C:$C,$A21,Impact_Input!$D:$D,F$17)) -> 0 | G21: =TANH(Parameters!$B$24*SUMIFS(Impact_Input!$N:$N,Impact_Input!$B:$B,"B",Impact_Input!$C:$C,$A21,Impact_Input!$D:$D,G$17)) -> 0 | H21: =TANH(Parameters!$B$24*SUMIFS(Impact_Input!$N:$N,Impact_Input!$B:$B,"B",Impact_Input!$C:$C,$A21,Impact_Input!$D:$D,H$17)) -> 0
A22: U5 | B22: =TANH(Parameters!$B$24*SUMIFS(Impact_Input!$N:$N,Impact_Input!$B:$B,"B",Impact_Input!$C:$C,$A22,Impact_Input!$D:$D,B$17)) -> 0 | C22: =TANH(Parameters!$B$24*SUMIFS(Impact_Input!$N:$N,Impact_Input!$B:$B,"B",Impact_Input!$C:$C,$A22,Impact_Input!$D:$D,C$17)) -> 0 | D22: =TANH(Parameters!$B$24*SUMIFS(Impact_Input!$N:$N,Impact_Input!$B:$B,"B",Impact_Input!$C:$C,$A22,Impact_Input!$D:$D,D$17)) -> 0 | E22: =TANH(Parameters!$B$24*SUMIFS(Impact_Input!$N:$N,Impact_Input!$B:$B,"B",Impact_Input!$C:$C,$A22,Impact_Input!$D:$D,E$17)) -> 0 | F22: =TANH(Parameters!$B$24*SUMIFS(Impact_Input!$N:$N,Impact_Input!$B:$B,"B",Impact_Input!$C:$C,$A22,Impact_Input!$D:$D,F$17)) -> 0 | G22: =TANH(Parameters!$B$24*SUMIFS(Impact_Input!$N:$N,Impact_Input!$B:$B,"B",Impact_Input!$C:$C,$A22,Impact_Input!$D:$D,G$17)) -> 0 | H22: =TANH(Parameters!$B$24*SUMIFS(Impact_Input!$N:$N,Impact_Input!$B:$B,"B",Impact_Input!$C:$C,$A22,Impact_Input!$D:$D,H$17)) -> 0
A23: U6 | B23: =TANH(Parameters!$B$24*SUMIFS(Impact_Input!$N:$N,Impact_Input!$B:$B,"B",Impact_Input!$C:$C,$A23,Impact_Input!$D:$D,B$17)) -> 0 | C23: =TANH(Parameters!$B$24*SUMIFS(Impact_Input!$N:$N,Impact_Input!$B:$B,"B",Impact_Input!$C:$C,$A23,Impact_Input!$D:$D,C$17)) -> 0 | D23: =TANH(Parameters!$B$24*SUMIFS(Impact_Input!$N:$N,Impact_Input!$B:$B,"B",Impact_Input!$C:$C,$A23,Impact_Input!$D:$D,D$17)) -> 0 | E23: =TANH(Parameters!$B$24*SUMIFS(Impact_Input!$N:$N,Impact_Input!$B:$B,"B",Impact_Input!$C:$C,$A23,Impact_Input!$D:$D,E$17)) -> 0 | F23: =TANH(Parameters!$B$24*SUMIFS(Impact_Input!$N:$N,Impact_Input!$B:$B,"B",Impact_Input!$C:$C,$A23,Impact_Input!$D:$D,F$17)) -> 0 | G23: =TANH(Parameters!$B$24*SUMIFS(Impact_Input!$N:$N,Impact_Input!$B:$B,"B",Impact_Input!$C:$C,$A23,Impact_Input!$D:$D,G$17)) -> 0 | H23: =TANH(Parameters!$B$24*SUMIFS(Impact_Input!$N:$N,Impact_Input!$B:$B,"B",Impact_Input!$C:$C,$A23,Impact_Input!$D:$D,H$17)) -> 0
A24: U7 | B24: =TANH(Parameters!$B$24*SUMIFS(Impact_Input!$N:$N,Impact_Input!$B:$B,"B",Impact_Input!$C:$C,$A24,Impact_Input!$D:$D,B$17)) -> 0 | C24: =TANH(Parameters!$B$24*SUMIFS(Impact_Input!$N:$N,Impact_Input!$B:$B,"B",Impact_Input!$C:$C,$A24,Impact_Input!$D:$D,C$17)) -> 0 | D24: =TANH(Parameters!$B$24*SUMIFS(Impact_Input!$N:$N,Impact_Input!$B:$B,"B",Impact_Input!$C:$C,$A24,Impact_Input!$D:$D,D$17)) -> 0 | E24: =TANH(Parameters!$B$24*SUMIFS(Impact_Input!$N:$N,Impact_Input!$B:$B,"B",Impact_Input!$C:$C,$A24,Impact_Input!$D:$D,E$17)) -> 0 | F24: =TANH(Parameters!$B$24*SUMIFS(Impact_Input!$N:$N,Impact_Input!$B:$B,"B",Impact_Input!$C:$C,$A24,Impact_Input!$D:$D,F$17)) -> 0 | G24: =TANH(Parameters!$B$24*SUMIFS(Impact_Input!$N:$N,Impact_Input!$B:$B,"B",Impact_Input!$C:$C,$A24,Impact_Input!$D:$D,G$17)) -> 0 | H24: =TANH(Parameters!$B$24*SUMIFS(Impact_Input!$N:$N,Impact_Input!$B:$B,"B",Impact_Input!$C:$C,$A24,Impact_Input!$D:$D,H$17)) -> -0.010211456

Sheet NCRC
A1: LEVEL 1: NON-COMPENSATORY RIGHTS CONSTRAINT (NCRC)
A3: Reference: Ripple_Logic v8.6 Section 7.0
A4: Rule: For each right r, MIN impact across coverage set must be ≥ θ_r
A5: NCRC RIGHTS FLOOR CHECK (Min_I_rights vs θ_r; PASS if Min_I_rights ≥ θ_r)
A6: OPTION A RIGHTS CHECK
A7: Right | B7: Priority | C7: θ_r | D7: Min_I_rights_A | E7: Min_I_rights_B | F7: Pass_A | G7: Pass_B | H7: Worst_Cell_A | I7: Worst_Cell_B
A8: LIFE | B8: 1 | C8: -0.9 | D8: =_xlfn.MINIFS(Rights_Coverage_View!$M$2:$M$71,Rights_Coverage_View!$L$2:$L$71,$A8) -> 0 | E8: =_xlfn.MINIFS(Rights_Coverage_View!$N$2:$N$71,Rights_Coverage_View!$L$2:$L$71,$A8) -> 0 | F8: =IF(D8>=$C8,"PASS","FAIL") -> PASS | G8: =IF(E8>=$C8,"PASS","FAIL") -> PASS | H8: =IFERROR("Rights_Coverage_View!"&ADDRESS(_xludf.aggregate(15,6,ROW(Rights_Coverage_View!$H$2:$H$100)/((Rights_Coverage_View!$B$2:$B$100=$A8)*(Rights_Coverage_View!$H$2:$H$100=D8)*(Rights_Coverage_View!$H$2:$H$100<>"")),1),8,4),"ERR") -> ERR | I8: =IFERROR("Rights_Coverage_View!"&ADDRESS(_xludf.aggregate(15,6,ROW(Rights_Coverage_View!$I$2:$I$100)/((Rights_Coverage_View!$B$2:$B$100=$A8)*(Rights_Coverage_View!$I$2:$I$100=E8)*(Rights_Coverage_View!$I$2:$I$100<>"")),1),9,4),"ERR") -> ERR
A9: BODY | B9: 2 | C9: -0.7 | D9: =_xlfn.MINIFS(Rights_Coverage_View!$M$2:$M$71,Rights_Coverage_View!$L$2:$L$71,$A9) -> 0 | E9: =_xlfn.MINIFS(Rights_Coverage_View!$N$2:$N$71,Rights_Coverage_View!$L$2:$L$71,$A9) -> 0 | F9: =IF(D9>=$C9,"PASS","FAIL") -> PASS | G9: =IF(E9>=$C9,"PASS","FAIL") -> PASS | H9: =IFERROR("Rights_Coverage_View!"&ADDRESS(_xludf.aggregate(15,6,ROW(Rights_Coverage_View!$H$2:$H$100)/((Rights_Coverage_View!$B$2:$B$100=$A9)*(Rights_Coverage_View!$H$2:$H$100=D9)*(Rights_Coverage_View!$H$2:$H$100<>"")),1),8,4),"ERR") -> ERR | I9: =IFERROR("Rights_Coverage_View!"&ADDRESS(_xludf.aggregate(15,6,ROW(Rights_Coverage_View!$I$2:$I$100)/((Rights_Coverage_View!$B$2:$B$100=$A9)*(Rights_Coverage_View!$I$2:$I$100=E9)*(Rights_Coverage_View!$I$2:$I$100<>"")),1),9,4),"ERR") -> ERR
A10: ECOL | B10: 3 | C10: -0.65 | D10: =_xlfn.MINIFS(Rights_Coverage_View!$M$2:$M$71,Rights_Coverage_View!$L$2:$L$71,$A10) -> 0 | E10: =_xlfn.MINIFS(Rights_Coverage_View!$N$2:$N$71,Rights_Coverage_View!$L$2:$L$71,$A10) -> -0.010211456 | F10: =IF(D10>=$C10,"PASS","FAIL") -> PASS | G10: =IF(E10>=$C10,"PASS","FAIL") -> PASS | H10: =IFERROR("Rights_Coverage_View!"&ADDRESS(_xludf.aggregate(15,6,ROW(Rights_Coverage_View!$H$2:$H$100)/((Rights_Coverage_View!$B$2:$B$100=$A10)*(Rights_Coverage_View!$H$2:$H$100=D10)*(Rights_Coverage_View!$H$2:$H$100<>"")),1),8,4),"ERR") -> ERR | I10: =IFERROR("Rights_Coverage_View!"&ADDRESS(_xludf.aggregate(15,6,ROW(Rights_Coverage_View!$I$2:$I$100)/((Rights_Coverage_View!$B$2:$B$100=$A10)*(Rights_Coverage_View!$I$2:$I$100=E10)*(Rights_Coverage_View!$I$2:$I$100<>"")),1),9,4),"ERR") -> ERR
A11: LBTY | B11: 4 | C11: -0.65 | D11: =_xlfn.MINIFS(Rights_Coverage_View!$M$2:$M$71,Rights_Coverage_View!$L$2:$L$71,$A11) -> -0.080725687 | E11: =_xlfn.MINIFS(Rights_Coverage_View!$N$2:$N$71,Rights_Coverage_View!$L$2:$L$71,$A11) -> -0.046333568 | F11: =IF(D11>=$C11,"PASS","FAIL") -> PASS | G11: =IF(E11>=$C11,"PASS","FAIL") -> PASS | H11: =IFERROR("Rights_Coverage_View!"&ADDRESS(_xludf.aggregate(15,6,ROW(Rights_Coverage_View!$H$2:$H$100)/((Rights_Coverage_View!$B$2:$B$100=$A11)*(Rights_Coverage_View!$H$2:$H$100=D11)*(Rights_Coverage_View!$H$2:$H$100<>"")),1),8,4),"ERR") -> ERR | I11: =IFERROR("Rights_Coverage_View!"&ADDRESS(_xludf.aggregate(15,6,ROW(Rights_Coverage_View!$I$2:$I$100)/((Rights_Coverage_View!$B$2:$B$100=$A11)*(Rights_Coverage_View!$I$2:$I$100=E11)*(Rights_Coverage_View!$I$2:$I$100<>"")),1),9,4),"ERR") -> ERR
A12: NEED | B12: 5 | C12: -0.5 | D12: =_xlfn.MINIFS(Rights_Coverage_View!$M$2:$M$71,Rights_Coverage_View!$L$2:$L$71,$A12) -> -0.085569436 | E12: =_xlfn.MINIFS(Rights_Coverage_View!$N$2:$N$71,Rights_Coverage_View!$L$2:$L$71,$A12) -> -0.0184759 | F12: =IF(D12>=$C12,"PASS","FAIL") -> PASS | G12: =IF(E12>=$C12,"PASS","FAIL") -> PASS | H12: =IFERROR("Rights_Coverage_View!"&ADDRESS(_xludf.aggregate(15,6,ROW(Rights_Coverage_View!$H$2:$H$100)/((Rights_Coverage_View!$B$2:$B$100=$A12)*(Rights_Coverage_View!$H$2:$H$100=D12)*(Rights_Coverage_View!$H$2:$H$100<>"")),1),8,4),"ERR") -> ERR | I12: =IFERROR("Rights_Coverage_View!"&ADDRESS(_xludf.aggregate(15,6,ROW(Rights_Coverage_View!$I$2:$I$100)/((Rights_Coverage_View!$B$2:$B$100=$A12)*(Rights_Coverage_View!$I$2:$I$100=E12)*(Rights_Coverage_View!$I$2:$I$100<>"")),1),9,4),"ERR") -> ERR
